#VRML_SIM R2025a utf8

EXTERNPROTO "https://raw.githubusercontent.com/cyberbotics/webots/R2025a/projects/objects/backgrounds/protos/TexturedBackground.proto"
EXTERNPROTO "https://raw.githubusercontent.com/cyberbotics/webots/R2025a/projects/objects/backgrounds/protos/TexturedBackgroundLight.proto"

WorldInfo {
}
Viewpoint {
  orientation -0.5773502691896258 0.5773502691896258 0.5773502691896258 2.0944
  position -0.15080889233543548 0.02379999720024377 3.3811209523419627
}
TexturedBackground {
}
TexturedBackgroundLight {
}
Robot {
  children [
    DEF base Solid {
      children [
        DEF base_shape Shape {
          geometry Box {
            size 1 0.1 0.1
          }
        }
      ]
      name "base"
      boundingObject USE base_shape
    }
    DEF joint1 HingeJoint {
      jointParameters HingeJointParameters {
        position 27.76421798860499
        axis 0 0 1
        anchor -0.5 0 0
      }
      device [
        RotationalMotor {
          name "motor1"
        }
      ]
      endPoint DEF link1 Solid {
        translation -0.5487501519820986 -0.08755164948030554 0.09999999999999999
        rotation -0.0018886599535956937 -0.00209356795659746 0.9999960249604949 4.203507112367312
        children [
          DEF link1_shape Shape {
            appearance Appearance {
              material Material {
                diffuseColor 1 0 0
              }
            }
            geometry Box {
              size 0.2 0.1 0.1
            }
          }
          HingeJoint {
            jointParameters HingeJointParameters {
              position -27.47203071651299
              axis 0 0 1
              anchor 0.2 0 0
            }
            endPoint DEF link2 Solid {
              translation 0.2695288968032017 0.07186455032402142 -0.002952199079559253
              rotation 9.642233578723739e-05 5.41527405076142e-05 -0.9999999938851069 3.0402024787437925
              children [
                Pose {
                  translation 0.3 0 0.1
                  children [
                    DEF link2_shape Shape {
                      appearance Appearance {
                        material Material {
                          diffuseColor 0 1 0
                        }
                      }
                      geometry Box {
                        size 0.6 0.1 0.1
                      }
                    }
                  ]
                }
                HingeJoint {
                  jointParameters HingeJointParameters {
                    position 0.31198045689161513
                    axis 0 0 1
                    anchor 0.6 0 0
                  }
                  endPoint DEF link3 Solid {
                    translation 0.6000007634216735 -5.939911240011655e-07 -0.00017800410137575718
                    rotation -3.885378974527012e-06 -1.4684943219112592e-05 -0.9999999998846283 1.3988702825069557
                    children [
                      Pose {
                        translation 0.45 0 0
                        children [
                          DEF link3_shape Shape {
                            appearance Appearance {
                              material Material {
                                diffuseColor 0 0 1
                              }
                            }
                            geometry Box {
                              size 0.9 0.1 0.1
                            }
                          }
                        ]
                      }
                    ]
                    name "link3"
                    boundingObject Pose {
                      translation 0.45 0 0
                      children [
                        USE link3_shape
                      ]
                    }
                    physics Physics {
                    }
                    linearVelocity -3.766354923594735e-08 3.924614609913051e-09 -1.3295562876009674e-06
                    angularVelocity -8.293548419721104e-08 -3.8537845395389735e-07 1.0823098970919018e-08
                  }
                }
              ]
              name "link2"
              boundingObject Pose {
                translation 0.3 0 0.1
                children [
                  USE link2_shape
                ]
              }
              physics Physics {
              }
              linearVelocity -1.2592627460908805e-07 3.354093182187784e-08 -1.5826060607274093e-06
              angularVelocity -5.758256125917658e-08 -2.327464009005724e-07 -2.35926460791859e-07
            }
          }
        ]
        name "link1"
        boundingObject USE link1_shape
        physics Physics {
        }
        linearVelocity -6.021140191792011e-08 1.613467388583752e-08 -9.172640671977105e-07
        angularVelocity 6.860628249951027e-08 -1.700378348408918e-07 -4.837446238046303e-07
      }
    }
    DEF joint4 HingeJoint {
      jointParameters HingeJointParameters {
        position 0.6041694008081687
        axis 0 0 1
        anchor 0.5 0 0
      }
      endPoint SolidReference {
        solidName "link3"
      }
    }
  ]
  controller "fourbar_controller1"
}
