#VRML_SIM R2025a utf8

EXTERNPROTO "https://raw.githubusercontent.com/cyberbotics/webots/R2025a/projects/objects/backgrounds/protos/TexturedBackground.proto"
EXTERNPROTO "https://raw.githubusercontent.com/cyberbotics/webots/R2025a/projects/objects/backgrounds/protos/TexturedBackgroundLight.proto"

WorldInfo {
}
Viewpoint {
  orientation -0.5773502691896258 0.5773502691896258 0.5773502691896258 2.0944
  position -0.08904405228850862 0.2607596567927343 2.410331210110735
}
TexturedBackground {
}
TexturedBackgroundLight {
}
Robot {
  children [
    DEF base Solid {
      children [
        DEF base_shape Shape {
          geometry Box {
            size 1 0.1 0.1
          }
        }
      ]
      name "base"
      boundingObject USE base_shape
    }
    DEF joint1 HingeJoint {
      jointParameters HingeJointParameters {
        position -9.167559291771023e-05
        axis 0 0 1
        anchor -0.5 0 0
      }
      device [
        RotationalMotor {
          name "motor1"
        }
      ]
      endPoint DEF link1 Solid {
        translation -0.5001620078232412 0.10020686903833093 0.06283629999999996
        rotation -0.0028505974752551745 0.0014409457622216197 0.9999948988716614 1.5716014915251997
        children [
          DEF link1_shape Shape {
            appearance Appearance {
              material Material {
                diffuseColor 1 0 0
              }
            }
            geometry Box {
              size 0.2 0.1 0.1
            }
          }
          HingeJoint {
            jointParameters HingeJointParameters {
              position 2.576574321076722e-05
              axis 0 0 1
              anchor 0.2 0 0
            }
            endPoint DEF link2 Solid {
              translation 0.10000610131471788 3.618924739428724e-05 -0.002952199079559257
              rotation -3.550249621476892e-05 0.0003197408835385587 -0.9999999482526688 0.700887257958665
              children [
                Pose {
                  translation 0.3 0 0.1
                  children [
                    DEF link2_shape Shape {
                      appearance Appearance {
                        material Material {
                          diffuseColor 0 1 0
                        }
                      }
                      geometry Box {
                        size 0.6 0.1 0.1
                      }
                    }
                  ]
                }
                HingeJoint {
                  jointParameters HingeJointParameters {
                    position -3.945959359296974e-05
                    axis 0 0 1
                    anchor 0.6 0 0
                  }
                  endPoint DEF link3 Solid {
                    translation 0.6000005442158162 -7.996669634750677e-07 -0.00017800410137575745
                    rotation -5.219368186483244e-06 -1.185709649990886e-05 -0.9999999999160837 1.7108901989615863
                    children [
                      Pose {
                        translation 0.45 0 0
                        children [
                          DEF link3_shape Shape {
                            appearance Appearance {
                              material Material {
                                diffuseColor 0 0 1
                              }
                            }
                            geometry Box {
                              size 0.9 0.1 0.1
                            }
                          }
                        ]
                      }
                    ]
                    name "link3"
                    boundingObject Pose {
                      translation 0.45 0 0
                      children [
                        USE link3_shape
                      ]
                    }
                    physics Physics {
                    }
                    linearVelocity 5.229543309158809e-09 4.4232749219352575e-08 -1.3875891783452186e-06
                    angularVelocity -3.9448970208520104e-07 -2.473226058137625e-07 -6.553137330292808e-08
                  }
                }
              ]
              name "link2"
              boundingObject Pose {
                translation 0.3 0 0.1
                children [
                  USE link2_shape
                ]
              }
              physics Physics {
              }
              linearVelocity 4.494603383046678e-08 7.743436806379132e-08 -1.6210784074248372e-06
              angularVelocity -3.746359459230764e-07 -9.487227502781858e-08 1.230549661015689e-07
            }
          }
        ]
        name "link1"
        boundingObject USE link1_shape
        physics Physics {
        }
        linearVelocity 2.1809826810104037e-08 1.8066136613369742e-08 -9.017849666860732e-07
        angularVelocity -2.9378279761272384e-07 -4.829804579004063e-08 -2.3458562994408014e-07
      }
    }
    DEF joint4 HingeJoint {
      jointParameters HingeJointParameters {
        position -0.00013222517647903942
        axis 0 0 1
        anchor 0.5 0 0
      }
      endPoint SolidReference {
        solidName "link3"
      }
    }
  ]
  controller "fourbar_controller1"
}
